main/test_files/test-f1-4.txt
400000
sell 98
buy 82
sell 109
buy 75
sell 106
buy 95
sell 85
buy 84
sell 103
buy 56
sell 130
buy 62
sell 110
buy 80
sell 95
buy 100
sell 120
buy 70
sell 93
buy 57
sell 97
buy 98
sell 108
buy 67
sell 120
buy 88
sell 84
buy 67
sell 105
buy 99
sell 105
buy 69
sell 109
buy 95
sell 129
buy 83
sell 111
buy 86
sell 121
buy 81
sell 81
buy 71
sell 84
buy 98
sell 86
buy 51
sell 96
buy 93
sell 121
buy 62
sell 111
buy 91
sell 94
buy 83
sell 97
buy 90
sell 106
buy 54
sell 118
buy 100
sell 117
buy 93
sell 115
buy 85
sell 124
buy 95
sell 84
buy 83
sell 128
buy 92
sell 86
buy 73
sell 126
buy 82
sell 88
buy 93
sell 88
buy 97
sell 93
buy 67
sell 129
buy 81
sell 126
buy 58
sell 84
buy 67
sell 84
buy 84
sell 104
buy 80
sell 108
buy 57
sell 104
buy 64
sell 112
buy 55
sell 130
buy 91
sell 120
buy 53
sell 94
buy 97
sell 88
buy 64
sell 120
buy 100
sell 103
buy 94
sell 97
buy 98
sell 126
buy 87
sell 101
buy 67
sell 106
buy 75
sell 87
buy 75
sell 119
buy 82
sell 89
buy 89
sell 93
buy 71
sell 99
buy 69
sell 126
buy 99
sell 115
buy 96
sell 117
buy 88
sell 93
buy 53
sell 114
buy 69
sell 130
buy 73
sell 117
buy 69
sell 127
buy 64
sell 128
buy 66
sell 125
buy 86
sell 93
buy 66
sell 84
buy 74
sell 130
buy 79
sell 109
buy 89
sell 100
buy 95
sell 98
buy 56
sell 122
buy 66
sell 89
buy 86
sell 91
buy 62
sell 84
buy 73
sell 93
buy 93
sell 125
buy 70
sell 111
buy 77
sell 90
buy 94
sell 114
buy 74
sell 121
buy 81
sell 124
buy 58
sell 122
buy 51
sell 108
buy 58
sell 113
buy 68
sell 105
buy 69
sell 122
buy 69
sell 100
buy 71
sell 96
buy 77
sell 129
buy 74
sell 124
buy 82
sell 86
buy 71
sell 93
buy 72
sell 106
buy 90
sell 107
buy 93
sell 123
buy 53
sell 105
buy 80
sell 112
buy 79
sell 83
buy 75
sell 118
buy 79
sell 107
buy 52
sell 117
buy 75
sell 128
buy 95
sell 124
buy 65
sell 107
buy 83
sell 118
buy 60
sell 94
buy 95
sell 119
buy 83
sell 100
buy 82
sell 96
buy 100
sell 111
buy 86
sell 92
buy 70
sell 125
buy 76
sell 122
buy 52
sell 101
buy 85
sell 92
buy 60
sell 104
buy 90
sell 85
buy 64
sell 125
buy 100
sell 117
buy 78
sell 117
buy 69
sell 107
buy 60
sell 120
buy 93
sell 96
buy 59
sell 101
buy 71
sell 97
buy 100
sell 101
buy 53
sell 108
buy 54
sell 109
buy 54
sell 104
buy 69
sell 107
buy 57
sell 98
buy 74
sell 128
buy 56
sell 105
buy 50
sell 108
buy 91
sell 109
buy 83
sell 124
buy 100
sell 82
buy 83
sell 98
buy 67
sell 83
buy 95
sell 93
buy 96
sell 110
buy 92
sell 88
buy 92
sell 112
buy 78
sell 105
buy 53
sell 112
buy 77
sell 126
buy 73
sell 129
buy 67
sell 125
buy 87
sell 116
buy 71
sell 98
buy 67
sell 103
buy 78
sell 96
buy 61
sell 126
buy 80
sell 88
buy 55
sell 95
buy 99
sell 114
buy 64
sell 129
buy 65
sell 101
buy 99
sell 95
buy 90
sell 81
buy 76
sell 108
buy 68
sell 111
buy 100
sell 91
buy 70
sell 106
buy 86
sell 86
buy 91
sell 87
buy 89
sell 98
buy 69
sell 82
buy 73
sell 104
buy 100
sell 116
buy 76
sell 99
buy 73
sell 102
buy 74
sell 87
buy 87
sell 86
buy 54
sell 109
buy 68
sell 126
buy 97
sell 93
buy 78
sell 104
buy 65
sell 100
buy 94
sell 97
buy 50
sell 128
buy 59
sell 102
buy 87
sell 111
buy 52
sell 92
buy 53
sell 103
buy 56
sell 107
buy 60
sell 81
buy 89
sell 86
buy 51
sell 128
buy 66
sell 118
buy 86
sell 108
buy 52
sell 88
buy 60
sell 120
buy 56
sell 104
buy 67
sell 100
buy 68
sell 120
buy 62
sell 95
buy 88
sell 97
buy 62
sell 112
buy 76
sell 103
buy 94
sell 120
buy 66
sell 100
buy 70
sell 103
buy 95
sell 119
buy 74
sell 121
buy 71
sell 90
buy 56
sell 93
buy 83
sell 109
buy 57
sell 86
buy 95
sell 121
buy 96
sell 80
buy 60
sell 80
buy 76
sell 85
buy 78
sell 106
buy 98
sell 96
buy 72
sell 129
buy 53
sell 116
buy 89
sell 116
buy 98
sell 110
buy 99
sell 102
buy 60
sell 118
buy 94
sell 108
buy 76
sell 80
buy 62
sell 97
buy 67
sell 114
buy 82
sell 110
buy 97
sell 86
buy 95
sell 82
buy 66
sell 100
buy 79
sell 88
buy 91
sell 95
buy 65
sell 120
buy 81
sell 82
buy 96
sell 114
buy 81
sell 122
buy 60
sell 89
buy 54
sell 115
buy 65
sell 87
buy 50
sell 100
buy 78
sell 84
buy 61
sell 82
buy 96
sell 87
buy 96
sell 124
buy 84
sell 101
buy 72
sell 107
buy 81
sell 87
buy 86
sell 103
buy 56
sell 87
buy 87
sell 103
buy 71
sell 82
buy 66
sell 91
buy 99
sell 109
buy 55
sell 91
buy 54
sell 80
buy 60
sell 89
buy 70
sell 116
buy 84
sell 128
buy 77
sell 112
buy 56
sell 103
buy 77
sell 102
buy 91
sell 101
buy 64
sell 118
buy 52
sell 122
buy 51
sell 86
buy 55
sell 112
buy 53
sell 91
buy 89
sell 96
buy 60
sell 92
buy 67
sell 85
buy 88
sell 96
buy 71
sell 119
buy 69
sell 85
buy 92
sell 92
buy 88
sell 126
buy 61
sell 83
buy 80
sell 81
buy 91
sell 113
buy 99
sell 101
buy 52
sell 105
buy 64
sell 125
buy 51
sell 89
buy 58
sell 121
buy 99
sell 82
buy 70
sell 118
buy 95
sell 113
buy 85
sell 106
buy 91
sell 106
buy 73
sell 115
buy 51
sell 102
buy 58
sell 94
buy 97
sell 127
buy 82
sell 83
buy 50
sell 81
buy 96
sell 80
buy 94
sell 97
buy 94
sell 108
buy 70
sell 115
buy 89
sell 101
buy 72
sell 111
buy 67
sell 130
buy 69
sell 122
buy 86
sell 117
buy 50
sell 97
buy 52
sell 82
buy 54
sell 89
buy 69
sell 91
buy 89
sell 81
buy 86
sell 119
buy 86
sell 92
buy 79
sell 98
buy 74
sell 90
buy 66
sell 81
buy 68
sell 121
buy 74
sell 85
buy 93
sell 112
buy 85
sell 87
buy 83
sell 115
buy 60
sell 130
buy 93
sell 127
buy 59
sell 115
buy 90
sell 109
buy 73
sell 84
buy 64
sell 110
buy 100
sell 109
buy 57
sell 109
buy 92
sell 110
buy 52
sell 100
buy 88
sell 105
buy 72
sell 82
buy 92
sell 99
buy 56
sell 121
buy 65
sell 129
buy 93
sell 114
buy 83
sell 129
buy 68
sell 120
buy 64
sell 114
buy 66
sell 93
buy 79
sell 125
buy 88
sell 115
buy 50
sell 85
buy 81
sell 100
buy 84
sell 97
buy 71
sell 120
buy 69
sell 110
buy 73
sell 97
buy 78
sell 89
buy 55
sell 104
buy 96
sell 99
buy 61
sell 83
buy 50
sell 95
buy 69
sell 105
buy 83
sell 129
buy 81
sell 115
buy 70
sell 94
buy 59
sell 115
buy 72
sell 115
buy 97
sell 83
buy 75
sell 117
buy 82
sell 108
buy 75
sell 95
buy 94
sell 93
buy 93
sell 116
buy 57
sell 86
buy 74
sell 103
buy 67
sell 118
buy 65
sell 115
buy 72
sell 97
buy 87
sell 86
buy 90
sell 98
buy 51
sell 96
buy 54
sell 83
buy 64
sell 113
buy 56
sell 98
buy 64
sell 128
buy 100
sell 80
buy 68
sell 120
buy 95
sell 117
buy 50
sell 92
buy 84
sell 97
buy 98
sell 114
buy 68
sell 80
buy 57
sell 97
buy 55
sell 129
buy 57
sell 105
buy 78
sell 97
buy 73
sell 105
buy 57
sell 119
buy 51
sell 88
buy 56
sell 88
buy 65
sell 103
buy 99
sell 83
buy 67
sell 109
buy 61
sell 121
buy 72
sell 110
buy 71
sell 94
buy 51
sell 120
buy 80
sell 105
buy 95
sell 89
buy 57
sell 109
buy 56
sell 103
buy 85
sell 127
buy 72
sell 117
buy 52
sell 104
buy 93
sell 101
buy 90
sell 115
buy 62
sell 119
buy 94
sell 118
buy 68
sell 120
buy 84
sell 82
buy 99
sell 104
buy 60
sell 119
buy 57
sell 105
buy 89
sell 94
buy 69
sell 127
buy 53
sell 114
buy 78
sell 121
buy 100
sell 112
buy 85
sell 108
buy 76
sell 94
buy 86
sell 94
buy 63
sell 93
buy 74
sell 90
buy 71
sell 80
buy 51
sell 127
buy 57
sell 86
buy 61
sell 125
buy 50
sell 119
buy 88
sell 104
buy 82
sell 99
buy 74
sell 105
buy 72
sell 114
buy 87
sell 87
buy 90
sell 102
buy 92
sell 109
buy 74
sell 104
buy 89
sell 105
buy 96
sell 80
buy 63
sell 96
buy 57
sell 124
buy 82
sell 124
buy 70
sell 96
buy 87
sell 117
buy 58
sell 102
buy 71
sell 91
buy 94
sell 93
buy 89
sell 80
buy 74
sell 91
buy 64
sell 115
buy 96
sell 87
buy 76
sell 129
buy 58
sell 120
buy 62
sell 130
buy 80
sell 122
buy 50
sell 89
buy 68
sell 114
buy 52
sell 99
buy 60
sell 84
buy 57
sell 110
buy 71
sell 106
buy 83
sell 107
buy 90
sell 125
buy 96
sell 104
buy 69
sell 130
buy 78
sell 108
buy 69
sell 103
buy 88
sell 110
buy 58
sell 125
buy 70
sell 123
buy 83
sell 99
buy 62
sell 83
buy 86
sell 117
buy 88
sell 97
buy 97
sell 106
buy 62
sell 88
buy 72
sell 126
buy 57
sell 93
buy 96
sell 112
buy 75
sell 97
buy 87
sell 105
buy 55
sell 94
buy 56
sell 123
buy 85
sell 129
buy 79
sell 126
buy 79
sell 83
buy 68
sell 116
buy 53
sell 112
buy 57
sell 95
buy 53
sell 124
buy 69
sell 95
buy 54
sell 110
buy 76
sell 104
buy 81
sell 121
buy 73
sell 102
buy 63
sell 105
buy 88
sell 92
buy 92
sell 93
buy 73
sell 105
buy 66
sell 126
buy 87
sell 117
buy 59
sell 124
buy 68
sell 113
buy 87
sell 97
buy 55
sell 86
