main/test_files/test-f1-5.txt
500000
sell 119
buy 54
sell 126
buy 64
sell 81
buy 52
sell 81
buy 53
sell 127
buy 93
sell 101
buy 97
sell 123
buy 92
sell 116
buy 66
sell 116
buy 95
sell 100
buy 50
sell 130
buy 73
sell 95
buy 83
sell 104
buy 72
sell 109
buy 96
sell 96
buy 71
sell 129
buy 100
sell 80
buy 62
sell 88
buy 82
sell 130
buy 72
sell 103
buy 88
sell 125
buy 91
sell 80
buy 59
sell 118
buy 62
sell 124
buy 59
sell 87
buy 73
sell 118
buy 98
sell 103
buy 96
sell 114
buy 74
sell 127
buy 67
sell 84
buy 97
sell 122
buy 100
sell 120
buy 51
sell 107
buy 77
sell 106
buy 56
sell 98
buy 64
sell 118
buy 91
sell 129
buy 55
sell 126
buy 81
sell 90
buy 52
sell 87
buy 77
sell 107
buy 53
sell 111
buy 94
sell 113
buy 61
sell 81
buy 72
sell 122
buy 61
sell 118
buy 79
sell 80
buy 64
sell 117
buy 77
sell 129
buy 52
sell 109
buy 53
sell 87
buy 94
sell 93
buy 68
sell 111
buy 79
sell 86
buy 85
sell 85
buy 85
sell 125
buy 83
sell 118
buy 74
sell 123
buy 80
sell 128
buy 65
sell 92
buy 91
sell 102
buy 95
sell 128
buy 88
sell 91
buy 74
sell 84
buy 99
sell 92
buy 65
sell 86
buy 88
sell 103
buy 98
sell 86
buy 93
sell 84
buy 59
sell 96
buy 88
sell 121
buy 63
sell 83
buy 84
sell 91
buy 97
sell 122
buy 72
sell 125
buy 52
sell 115
buy 87
sell 101
buy 63
sell 88
buy 91
sell 98
buy 98
sell 109
buy 71
sell 126
buy 51
sell 118
buy 94
sell 124
buy 95
sell 114
buy 87
sell 118
buy 51
sell 103
buy 94
sell 98
buy 92
sell 107
buy 88
sell 115
buy 98
sell 124
buy 87
sell 99
buy 83
sell 107
buy 100
sell 85
buy 86
sell 100
buy 76
sell 127
buy 78
sell 104
buy 85
sell 98
buy 79
sell 100
buy 54
sell 88
buy 91
sell 125
buy 62
sell 90
buy 84
sell 99
buy 83
sell 98
buy 63
sell 87
buy 64
sell 85
buy 76
sell 86
buy 77
sell 122
buy 73
sell 113
buy 85
sell 100
buy 64
sell 115
buy 86
sell 94
buy 80
sell 106
buy 81
sell 93
buy 56
sell 125
buy 53
sell 120
buy 61
sell 122
buy 58
sell 104
buy 50
sell 109
buy 84
sell 109
buy 92
sell 95
buy 71
sell 106
buy 71
sell 101
buy 51
sell 86
buy 89
sell 108
buy 79
sell 99
buy 52
sell 98
buy 77
sell 116
buy 82
sell 97
buy 100
sell 118
buy 92
sell 119
buy 55
sell 83
buy 64
sell 111
buy 77
sell 129
buy 87
sell 92
buy 87
sell 129
buy 53
sell 108
buy 50
sell 127
buy 75
sell 127
buy 84
sell 106
buy 94
sell 91
buy 62
sell 95
buy 74
sell 114
buy 99
sell 117
buy 74
sell 92
buy 61
sell 89
buy 90
sell 99
buy 93
sell 129
buy 83
sell 127
buy 92
sell 113
buy 100
sell 103
buy 84
sell 89
buy 74
sell 100
buy 70
sell 114
buy 64
sell 100
buy 58
sell 81
buy 61
sell 128
buy 56
sell 119
buy 94
sell 112
buy 69
sell 110
buy 90
sell 97
buy 93
sell 99
buy 58
sell 80
buy 85
sell 107
buy 72
sell 110
buy 52
sell 90
buy 99
sell 95
buy 55
sell 104
buy 94
sell 123
buy 63
sell 86
buy 96
sell 81
buy 64
sell 116
buy 58
sell 99
buy 65
sell 110
buy 86
sell 119
buy 52
sell 120
buy 68
sell 106
buy 70
sell 122
buy 50
sell 106
buy 53
sell 109
buy 86
sell 99
buy 63
sell 102
buy 77
sell 83
buy 82
sell 120
buy 91
sell 81
buy 60
sell 93
buy 91
sell 96
buy 85
sell 127
buy 71
sell 98
buy 58
sell 100
buy 73
sell 104
buy 95
sell 101
buy 50
sell 86
buy 96
sell 98
buy 93
sell 118
buy 96
sell 127
buy 74
sell 120
buy 65
sell 86
buy 50
sell 111
buy 94
sell 127
buy 81
sell 130
buy 63
sell 102
buy 87
sell 116
buy 69
sell 93
buy 87
sell 116
buy 90
sell 115
buy 55
sell 102
buy 79
sell 94
buy 69
sell 112
buy 65
sell 117
buy 81
sell 104
buy 99
sell 92
buy 75
sell 83
buy 69
sell 91
buy 72
sell 96
buy 93
sell 122
buy 63
sell 84
buy 84
sell 125
buy 52
sell 100
buy 100
sell 119
buy 64
sell 111
buy 50
sell 120
buy 77
sell 101
buy 84
sell 86
buy 81
sell 124
buy 85
sell 108
buy 60
sell 108
buy 56
sell 108
buy 90
sell 106
buy 63
sell 108
buy 99
sell 130
buy 84
sell 107
buy 53
sell 115
buy 56
sell 109
buy 98
sell 95
buy 76
sell 87
buy 74
sell 81
buy 83
sell 87
buy 73
sell 126
buy 59
sell 113
buy 94
sell 83
buy 99
sell 116
buy 98
sell 80
buy 68
sell 92
buy 74
sell 106
buy 54
sell 106
buy 92
sell 103
buy 84
sell 84
buy 56
sell 95
buy 82
sell 111
buy 91
sell 93
buy 90
sell 110
buy 58
sell 83
buy 68
sell 118
buy 58
sell 126
buy 82
sell 111
buy 74
sell 122
buy 76
sell 109
buy 58
sell 101
buy 58
sell 129
buy 57
sell 91
buy 52
sell 105
buy 100
sell 101
buy 67
sell 121
buy 72
sell 84
buy 68
sell 103
buy 89
sell 124
buy 67
sell 90
buy 83
sell 110
buy 91
sell 106
buy 81
sell 115
buy 69
sell 93
buy 79
sell 128
buy 89
sell 94
buy 56
sell 125
buy 83
sell 95
buy 74
sell 92
buy 69
sell 100
buy 94
sell 120
buy 66
sell 123
buy 88
sell 130
buy 58
sell 129
buy 80
sell 81
buy 60
sell 93
buy 81
sell 107
buy 77
sell 100
buy 50
sell 98
buy 66
sell 89
buy 51
sell 98
buy 55
sell 130
buy 62
sell 96
buy 76
sell 98
buy 93
sell 117
buy 58
sell 86
buy 65
sell 92
buy 90
sell 101
buy 58
sell 125
buy 76
sell 119
buy 56
sell 111
buy 61
sell 130
buy 74
sell 103
buy 52
sell 125
buy 98
sell 120
buy 79
sell 88
buy 62
sell 120
buy 78
sell 124
buy 72
sell 112
buy 92
sell 108
buy 68
sell 122
buy 60
sell 98
buy 89
sell 124
buy 52
sell 111
buy 82
sell 88
buy 91
sell 128
buy 90
sell 96
buy 79
sell 80
buy 53
sell 84
buy 80
sell 82
buy 82
sell 85
buy 64
sell 92
buy 82
sell 91
buy 72
sell 123
buy 69
sell 82
buy 78
sell 96
buy 66
sell 119
buy 61
sell 127
buy 54
sell 87
buy 87
sell 118
buy 85
sell 99
buy 95
sell 84
buy 63
sell 87
buy 73
sell 108
buy 95
sell 130
buy 94
sell 107
buy 66
sell 96
buy 79
sell 108
buy 90
sell 120
buy 68
sell 128
buy 63
sell 85
buy 61
sell 124
buy 88
sell 80
buy 97
sell 93
buy 95
sell 125
buy 60
sell 126
buy 64
sell 91
buy 58
sell 105
buy 79
sell 108
buy 67
sell 128
buy 91
sell 87
buy 55
sell 102
buy 51
sell 108
buy 72
sell 126
buy 64
sell 109
buy 59
sell 112
buy 61
sell 125
buy 92
sell 97
buy 93
sell 111
buy 83
sell 93
buy 61
sell 106
buy 72
sell 90
buy 78
sell 96
buy 89
sell 111
buy 89
sell 84
buy 86
sell 103
buy 89
sell 122
buy 64
sell 122
buy 74
sell 130
buy 54
sell 115
buy 100
sell 93
buy 84
sell 87
buy 50
sell 104
buy 59
sell 85
buy 94
sell 87
buy 50
sell 82
buy 70
sell 85
buy 63
sell 84
buy 96
sell 100
buy 58
sell 99
buy 78
sell 102
buy 60
sell 108
buy 61
sell 98
buy 53
sell 87
buy 82
sell 88
buy 95
sell 92
buy 79
sell 87
buy 65
sell 121
buy 54
sell 123
buy 57
sell 114
buy 93
sell 119
buy 69
sell 130
buy 68
sell 111
buy 74
sell 82
buy 100
sell 120
buy 86
sell 123
buy 68
sell 105
buy 90
sell 98
buy 67
sell 101
buy 57
sell 120
buy 55
sell 105
buy 63
sell 104
buy 58
sell 96
buy 64
sell 120
buy 91
sell 109
buy 52
sell 100
buy 63
sell 105
buy 65
sell 87
buy 91
sell 108
buy 59
sell 111
buy 99
sell 129
buy 52
sell 102
buy 52
sell 86
buy 99
sell 108
buy 77
sell 127
buy 81
sell 92
buy 53
sell 116
buy 87
sell 99
buy 77
sell 114
buy 83
sell 113
buy 72
sell 104
buy 76
sell 95
buy 66
sell 107
buy 72
sell 99
buy 73
sell 106
buy 60
sell 90
buy 74
sell 94
buy 50
sell 109
buy 81
sell 94
buy 80
sell 127
buy 50
sell 113
buy 99
sell 118
buy 76
sell 117
buy 99
sell 116
buy 57
sell 119
buy 68
sell 91
buy 70
sell 80
buy 84
sell 92
buy 54
sell 86
buy 57
sell 115
buy 69
sell 113
buy 85
sell 104
buy 85
sell 88
buy 52
sell 106
buy 76
sell 95
buy 94
sell 105
buy 91
sell 110
buy 50
sell 91
buy 57
sell 97
buy 92
sell 81
buy 100
sell 87
buy 57
sell 86
buy 81
sell 81
buy 74
sell 99
buy 58
sell 110
buy 80
sell 85
buy 68
sell 106
buy 99
sell 106
buy 64
sell 92
buy 89
sell 100
buy 80
sell 105
buy 60
sell 106
buy 86
sell 104
buy 82
sell 121
buy 97
sell 129
buy 95
sell 91
buy 82
sell 111
buy 68
sell 111
buy 83
sell 117
buy 87
sell 82
buy 59
sell 82
buy 54
sell 111
buy 77
sell 114
buy 89
sell 98
buy 92
sell 86
buy 62
sell 125
buy 51
sell 111
buy 75
sell 110
buy 100
sell 97
buy 97
sell 94
buy 53
sell 105
buy 90
sell 80
buy 60
sell 100
buy 61
sell 110
buy 89
sell 80
buy 62
sell 95
buy 59
sell 81
buy 77
sell 90
buy 83
sell 113
buy 55
sell 130
buy 86
sell 98
buy 64
sell 126
buy 55
sell 119
buy 51
sell 130
buy 87
sell 86
buy 57
sell 102
buy 54
sell 98
buy 94
sell 112
buy 75
sell 116
buy 77
sell 82
buy 61
sell 130
buy 82
sell 94
buy 81
sell 96
buy 73
sell 112
buy 82
sell 100
buy 71
sell 119
buy 97
sell 100
buy 77
sell 117
buy 97
sell 92
buy 85
sell 111
buy 75
sell 113
buy 85
sell 127
buy 84
sell 88
buy 86
sell 102
buy 62
sell 109
